<?xml version="1.0" encoding="UTF-8"?>
<testng-results skipped="0" failed="5" total="6" passed="1">
  <reporter-output>
  </reporter-output>
  <suite name="Default suite" duration-ms="111716" started-at="2020-06-28T15:14:06Z" finished-at="2020-06-28T15:15:58Z">
    <groups>
    </groups>
    <test name="Default test" duration-ms="111716" started-at="2020-06-28T15:14:06Z" finished-at="2020-06-28T15:15:58Z">
      <class name="E2E_Tests">
        <test-method status="PASS" signature="createSession()" name="createSession" is-config="true" duration-ms="32" started-at="2020-06-28T15:14:06Z" finished-at="2020-06-28T15:14:06Z">
        </test-method>
        <test-method status="PASS" signature="agetToken()" name="agetToken" duration-ms="5002" started-at="2020-06-28T15:14:06Z" finished-at="2020-06-28T15:14:11Z">
        </test-method>
        <test-method status="FAIL" signature="bgetBooks()" name="bgetBooks" duration-ms="31329" started-at="2020-06-28T15:14:11Z" finished-at="2020-06-28T15:14:43Z">
          <exception class="java.lang.AssertionError">
            <message>
              <![CDATA[expected:<200> but was:<504>]]>
            </message>
            <full-stacktrace>
              <![CDATA[java.lang.AssertionError: expected:<200> but was:<504>
	at org.testng.Assert.fail(Assert.java:89)
	at org.testng.Assert.failNotEquals(Assert.java:480)
	at org.testng.Assert.assertEquals(Assert.java:118)
	at org.testng.Assert.assertEquals(Assert.java:365)
	at org.testng.Assert.assertEquals(Assert.java:375)
	at E2E_Tests.bgetBooks(E2E_Tests.java:72)
	at sun.reflect.NativeMethodAccessorImpl.invoke0(Native Method)
	at sun.reflect.NativeMethodAccessorImpl.invoke(Unknown Source)
	at sun.reflect.DelegatingMethodAccessorImpl.invoke(Unknown Source)
	at java.lang.reflect.Method.invoke(Unknown Source)
	at org.testng.internal.MethodInvocationHelper.invokeMethod(MethodInvocationHelper.java:76)
	at org.testng.internal.Invoker.invokeMethod(Invoker.java:673)
	at org.testng.internal.Invoker.invokeTestMethod(Invoker.java:846)
	at org.testng.internal.Invoker.invokeTestMethods(Invoker.java:1170)
	at org.testng.internal.TestMethodWorker.invokeTestMethods(TestMethodWorker.java:125)
	at org.testng.internal.TestMethodWorker.run(TestMethodWorker.java:109)
	at org.testng.TestRunner.runWorkers(TestRunner.java:1147)
	at org.testng.TestRunner.privateRun(TestRunner.java:749)
	at org.testng.TestRunner.run(TestRunner.java:600)
	at org.testng.SuiteRunner.runTest(SuiteRunner.java:317)
	at org.testng.SuiteRunner.runSequentially(SuiteRunner.java:312)
	at org.testng.SuiteRunner.privateRun(SuiteRunner.java:274)
	at org.testng.SuiteRunner.run(SuiteRunner.java:223)
	at org.testng.SuiteRunnerWorker.runSuite(SuiteRunnerWorker.java:52)
	at org.testng.SuiteRunnerWorker.run(SuiteRunnerWorker.java:86)
	at org.testng.TestNG.runSuitesSequentially(TestNG.java:1039)
	at org.testng.TestNG.runSuitesLocally(TestNG.java:964)
	at org.testng.TestNG.run(TestNG.java:900)
	at org.testng.remote.AbstractRemoteTestNG.run(AbstractRemoteTestNG.java:114)
	at org.testng.remote.RemoteTestNG.initAndRun(RemoteTestNG.java:251)
	at org.testng.remote.RemoteTestNG.main(RemoteTestNG.java:77)
]]>
            </full-stacktrace>
          </exception>
        </test-method>
        <test-method status="FAIL" signature="createUser()" name="createUser" duration-ms="1482" started-at="2020-06-28T15:14:43Z" finished-at="2020-06-28T15:14:44Z">
          <exception class="java.lang.AssertionError">
            <message>
              <![CDATA[Verified status code expected:<406> but was:<201>]]>
            </message>
            <full-stacktrace>
              <![CDATA[java.lang.AssertionError: Verified status code expected:<406> but was:<201>
	at org.testng.Assert.fail(Assert.java:89)
	at org.testng.Assert.failNotEquals(Assert.java:480)
	at org.testng.Assert.assertEquals(Assert.java:118)
	at org.testng.Assert.assertEquals(Assert.java:365)
	at E2E_Tests.createUser(E2E_Tests.java:158)
	at sun.reflect.NativeMethodAccessorImpl.invoke0(Native Method)
	at sun.reflect.NativeMethodAccessorImpl.invoke(Unknown Source)
	at sun.reflect.DelegatingMethodAccessorImpl.invoke(Unknown Source)
	at java.lang.reflect.Method.invoke(Unknown Source)
	at org.testng.internal.MethodInvocationHelper.invokeMethod(MethodInvocationHelper.java:76)
	at org.testng.internal.Invoker.invokeMethod(Invoker.java:673)
	at org.testng.internal.Invoker.invokeTestMethod(Invoker.java:846)
	at org.testng.internal.Invoker.invokeTestMethods(Invoker.java:1170)
	at org.testng.internal.TestMethodWorker.invokeTestMethods(TestMethodWorker.java:125)
	at org.testng.internal.TestMethodWorker.run(TestMethodWorker.java:109)
	at org.testng.TestRunner.runWorkers(TestRunner.java:1147)
	at org.testng.TestRunner.privateRun(TestRunner.java:749)
	at org.testng.TestRunner.run(TestRunner.java:600)
	at org.testng.SuiteRunner.runTest(SuiteRunner.java:317)
	at org.testng.SuiteRunner.runSequentially(SuiteRunner.java:312)
	at org.testng.SuiteRunner.privateRun(SuiteRunner.java:274)
	at org.testng.SuiteRunner.run(SuiteRunner.java:223)
	at org.testng.SuiteRunnerWorker.runSuite(SuiteRunnerWorker.java:52)
	at org.testng.SuiteRunnerWorker.run(SuiteRunnerWorker.java:86)
	at org.testng.TestNG.runSuitesSequentially(TestNG.java:1039)
	at org.testng.TestNG.runSuitesLocally(TestNG.java:964)
	at org.testng.TestNG.run(TestNG.java:900)
	at org.testng.remote.AbstractRemoteTestNG.run(AbstractRemoteTestNG.java:114)
	at org.testng.remote.RemoteTestNG.initAndRun(RemoteTestNG.java:251)
	at org.testng.remote.RemoteTestNG.main(RemoteTestNG.java:77)
]]>
            </full-stacktrace>
          </exception>
        </test-method>
        <test-method status="FAIL" signature="deleteBooks()" name="deleteBooks" duration-ms="32663" started-at="2020-06-28T15:14:44Z" finished-at="2020-06-28T15:15:17Z">
          <exception class="java.lang.AssertionError">
            <message>
              <![CDATA[expected:<504> but was:<204>]]>
            </message>
            <full-stacktrace>
              <![CDATA[java.lang.AssertionError: expected:<504> but was:<204>
	at org.testng.Assert.fail(Assert.java:89)
	at org.testng.Assert.failNotEquals(Assert.java:480)
	at org.testng.Assert.assertEquals(Assert.java:118)
	at org.testng.Assert.assertEquals(Assert.java:365)
	at org.testng.Assert.assertEquals(Assert.java:375)
	at E2E_Tests.deleteBooks(E2E_Tests.java:133)
	at sun.reflect.NativeMethodAccessorImpl.invoke0(Native Method)
	at sun.reflect.NativeMethodAccessorImpl.invoke(Unknown Source)
	at sun.reflect.DelegatingMethodAccessorImpl.invoke(Unknown Source)
	at java.lang.reflect.Method.invoke(Unknown Source)
	at org.testng.internal.MethodInvocationHelper.invokeMethod(MethodInvocationHelper.java:76)
	at org.testng.internal.Invoker.invokeMethod(Invoker.java:673)
	at org.testng.internal.Invoker.invokeTestMethod(Invoker.java:846)
	at org.testng.internal.Invoker.invokeTestMethods(Invoker.java:1170)
	at org.testng.internal.TestMethodWorker.invokeTestMethods(TestMethodWorker.java:125)
	at org.testng.internal.TestMethodWorker.run(TestMethodWorker.java:109)
	at org.testng.TestRunner.runWorkers(TestRunner.java:1147)
	at org.testng.TestRunner.privateRun(TestRunner.java:749)
	at org.testng.TestRunner.run(TestRunner.java:600)
	at org.testng.SuiteRunner.runTest(SuiteRunner.java:317)
	at org.testng.SuiteRunner.runSequentially(SuiteRunner.java:312)
	at org.testng.SuiteRunner.privateRun(SuiteRunner.java:274)
	at org.testng.SuiteRunner.run(SuiteRunner.java:223)
	at org.testng.SuiteRunnerWorker.runSuite(SuiteRunnerWorker.java:52)
	at org.testng.SuiteRunnerWorker.run(SuiteRunnerWorker.java:86)
	at org.testng.TestNG.runSuitesSequentially(TestNG.java:1039)
	at org.testng.TestNG.runSuitesLocally(TestNG.java:964)
	at org.testng.TestNG.run(TestNG.java:900)
	at org.testng.remote.AbstractRemoteTestNG.run(AbstractRemoteTestNG.java:114)
	at org.testng.remote.RemoteTestNG.initAndRun(RemoteTestNG.java:251)
	at org.testng.remote.RemoteTestNG.main(RemoteTestNG.java:77)
]]>
            </full-stacktrace>
          </exception>
        </test-method>
        <test-method status="FAIL" signature="egetUser()" name="egetUser" duration-ms="39931" started-at="2020-06-28T15:15:17Z" finished-at="2020-06-28T15:15:57Z">
          <exception class="java.lang.AssertionError">
            <message>
              <![CDATA[expected:<504> but was:<200>]]>
            </message>
            <full-stacktrace>
              <![CDATA[java.lang.AssertionError: expected:<504> but was:<200>
	at org.testng.Assert.fail(Assert.java:89)
	at org.testng.Assert.failNotEquals(Assert.java:480)
	at org.testng.Assert.assertEquals(Assert.java:118)
	at org.testng.Assert.assertEquals(Assert.java:365)
	at org.testng.Assert.assertEquals(Assert.java:375)
	at E2E_Tests.egetUser(E2E_Tests.java:144)
	at sun.reflect.NativeMethodAccessorImpl.invoke0(Native Method)
	at sun.reflect.NativeMethodAccessorImpl.invoke(Unknown Source)
	at sun.reflect.DelegatingMethodAccessorImpl.invoke(Unknown Source)
	at java.lang.reflect.Method.invoke(Unknown Source)
	at org.testng.internal.MethodInvocationHelper.invokeMethod(MethodInvocationHelper.java:76)
	at org.testng.internal.Invoker.invokeMethod(Invoker.java:673)
	at org.testng.internal.Invoker.invokeTestMethod(Invoker.java:846)
	at org.testng.internal.Invoker.invokeTestMethods(Invoker.java:1170)
	at org.testng.internal.TestMethodWorker.invokeTestMethods(TestMethodWorker.java:125)
	at org.testng.internal.TestMethodWorker.run(TestMethodWorker.java:109)
	at org.testng.TestRunner.runWorkers(TestRunner.java:1147)
	at org.testng.TestRunner.privateRun(TestRunner.java:749)
	at org.testng.TestRunner.run(TestRunner.java:600)
	at org.testng.SuiteRunner.runTest(SuiteRunner.java:317)
	at org.testng.SuiteRunner.runSequentially(SuiteRunner.java:312)
	at org.testng.SuiteRunner.privateRun(SuiteRunner.java:274)
	at org.testng.SuiteRunner.run(SuiteRunner.java:223)
	at org.testng.SuiteRunnerWorker.runSuite(SuiteRunnerWorker.java:52)
	at org.testng.SuiteRunnerWorker.run(SuiteRunnerWorker.java:86)
	at org.testng.TestNG.runSuitesSequentially(TestNG.java:1039)
	at org.testng.TestNG.runSuitesLocally(TestNG.java:964)
	at org.testng.TestNG.run(TestNG.java:900)
	at org.testng.remote.AbstractRemoteTestNG.run(AbstractRemoteTestNG.java:114)
	at org.testng.remote.RemoteTestNG.initAndRun(RemoteTestNG.java:251)
	at org.testng.remote.RemoteTestNG.main(RemoteTestNG.java:77)
]]>
            </full-stacktrace>
          </exception>
        </test-method>
        <test-method status="FAIL" signature="createBooks()" name="createBooks" duration-ms="1223" started-at="2020-06-28T15:15:57Z" finished-at="2020-06-28T15:15:58Z">
          <exception class="java.lang.AssertionError">
            <message>
              <![CDATA[expected:<400> but was:<201>]]>
            </message>
            <full-stacktrace>
              <![CDATA[java.lang.AssertionError: expected:<400> but was:<201>
	at org.testng.Assert.fail(Assert.java:89)
	at org.testng.Assert.failNotEquals(Assert.java:480)
	at org.testng.Assert.assertEquals(Assert.java:118)
	at org.testng.Assert.assertEquals(Assert.java:365)
	at org.testng.Assert.assertEquals(Assert.java:375)
	at E2E_Tests.createBooks(E2E_Tests.java:117)
	at sun.reflect.NativeMethodAccessorImpl.invoke0(Native Method)
	at sun.reflect.NativeMethodAccessorImpl.invoke(Unknown Source)
	at sun.reflect.DelegatingMethodAccessorImpl.invoke(Unknown Source)
	at java.lang.reflect.Method.invoke(Unknown Source)
	at org.testng.internal.MethodInvocationHelper.invokeMethod(MethodInvocationHelper.java:76)
	at org.testng.internal.Invoker.invokeMethod(Invoker.java:673)
	at org.testng.internal.Invoker.invokeTestMethod(Invoker.java:846)
	at org.testng.internal.Invoker.invokeTestMethods(Invoker.java:1170)
	at org.testng.internal.TestMethodWorker.invokeTestMethods(TestMethodWorker.java:125)
	at org.testng.internal.TestMethodWorker.run(TestMethodWorker.java:109)
	at org.testng.TestRunner.runWorkers(TestRunner.java:1147)
	at org.testng.TestRunner.privateRun(TestRunner.java:749)
	at org.testng.TestRunner.run(TestRunner.java:600)
	at org.testng.SuiteRunner.runTest(SuiteRunner.java:317)
	at org.testng.SuiteRunner.runSequentially(SuiteRunner.java:312)
	at org.testng.SuiteRunner.privateRun(SuiteRunner.java:274)
	at org.testng.SuiteRunner.run(SuiteRunner.java:223)
	at org.testng.SuiteRunnerWorker.runSuite(SuiteRunnerWorker.java:52)
	at org.testng.SuiteRunnerWorker.run(SuiteRunnerWorker.java:86)
	at org.testng.TestNG.runSuitesSequentially(TestNG.java:1039)
	at org.testng.TestNG.runSuitesLocally(TestNG.java:964)
	at org.testng.TestNG.run(TestNG.java:900)
	at org.testng.remote.AbstractRemoteTestNG.run(AbstractRemoteTestNG.java:114)
	at org.testng.remote.RemoteTestNG.initAndRun(RemoteTestNG.java:251)
	at org.testng.remote.RemoteTestNG.main(RemoteTestNG.java:77)
]]>
            </full-stacktrace>
          </exception>
        </test-method>
      </class>
    </test>
  </suite>
</testng-results>
